Workbook

Sheet BD
B1: 1 | C1: =+B1+1 -> 2 | D1: =+C1+1 -> 3 | E1: =+D1+1 -> 4 | F1: =+E1+1 -> 5 | G1: =+F1+1 -> 6 | H1: =+G1+1 -> 7 | I1: =+H1+1 -> 8 | J1: =+I1+1 -> 9 | ... BO1: =+BN1+1 -> 66
B3: FUENTE DE CAPTACION | C3: POZO N° 10 | H3: POZO N° 11 | M3: POZO N° 13 | R3: POZO MEDRANO | W3: MINAQUEROS | AB3: PLANTA DE TRATAMIENTO | AG3: GALERIAS FILTRANTES NARANJAL | AL3: POZO CHINCHA BAJA | AQ3: POZO CALLE MORA | AV3: POZO TAMBO DE MORA | BA3: CBAP HIJAYA | BF3: CBAP ALTO LARAN | BK3: CBAP PUEBLO NUEVO
B4: Dia | C4: PZ10_Caudal | D4: PZ10_Horas Activo | E4: PZ10 Inicio | F4: PZ10 Final | G4: PZ10 m3/día | H4: PZ11 Caudal PROM | I4: PZ 11 Horas Activo | J4: PZ 11 Inicio | K4: PZ 11 Final | L4: PZ 11 m3/día | M4: PZ 13 Caudal PROM | N4: PZ 13 Horas Activo | O4: PZ 13 Inicio | P4: PZ 13 Final | Q4: PZ 13 m3/día | R4: PZ MED Caudal PROM | S4: PZ MED Horas Activo | T4: PZ MED Inicio | U4: PZ MED Final | V4: PZ MED m3/día | W4: GF MIN Caudal PROM | X4: GF MIN Horas Activo | Y4: GF MIN Inicio | Z4: GF MIN Final | AA4: GF MIN m3/día | AB4: PTAP1 Caudal PROM | AC4: PTAP1 Horas Activo | AD4: PTAP1 Inicio | AE4: PTAP1 Final | AF4: PTAP1 m3/día | AG4: GF NAR Caudal PROM | AH4: GF NAR Horas Activo | AI4: GF NAR Inicio | AJ4: GF NAR Final | AK4: GF NAR m3/día | AL4: PZ CHB Caudal PROM | AM4: PZ CHB Horas Activo | AN4: PZ CHB Inicio | AO4: PZ CHB Final | AP4: PZ CHB m3/día | AQ4: PZ CM Caudal PROM | AR4: PZ CM Horas Activo | AS4: PZ CM Inicio | AT4: PZ CM Final | AU4: PZ CM m3/día | AV4: PZ TM Caudal PROM | AW4: PZ TM Horas Activo | AX4: PZ TM Inicio | AY4: PZ TM Final | AZ4: PZ TM m3/día | BA4: EBAP HIJA Caudal PROM | BB4: EBAP HIJA Horas Activo | BC4: EBAP HIJA Inicio | BD4: EBAP HIJA Final | BE4: EBAP HIJA m3/día | BF4: EBAP ALAR Caudal PROM | BG4: EBAP ALAR Horas Activo | BH4: EBAP ALAR Inicio | BI4: EBAP ALAR Final | BJ4: EBAP ALAR m3/día | BK4: EBAP PNUE Caudal PROM57 | BL4: EBAP PNUE Horas Activo | BM4: EBAP PNUE Inicio | BN4: EBAP PNUE Final | BO4: EBAP PNUE m3/día
A5: =MONTH(B5) -> 1 | B5: 46023 | C5: 38 | D5: =IFERROR(+G5/(C5*3.6)," ") -> 13.435673 | E5: 3735917 | F5: 3737755 | G5: =IFERROR((F5-E5)," ") -> 1838 | H5: 25 | I5: =IFERROR(+L5/(H5*3.6)," ") -> 0 | J5: 1970853 | K5: 1970853 | L5: =IFERROR((K5-J5)," ") -> 0 | M5: 38 | N5: =IFERROR(+Q5/(M5*3.6)," ") -> 0 | O5: 414403 | P5: 414403 | Q5: =IFERROR((P5-O5)," ") -> 0 | R5: =+BDFUENTES[[#This Row],[PZ MED m3/día]]/3.6/BDFUENTES[[#This Row],[PZ MED Horas Activo]] -> 29.854497 | S5: 21 | T5: 227566 | U5: 229823 | V5: =IFERROR((U5-T5)," ") -> 2257 | W5: =IFERROR((AA5/X5)/3.6," ") -> 338.47222 | X5: 24 | Y5: 622319 | Z5: 653820 | AA5: =IFERROR((Z5-Y5)," ")-2257 -> 29244 | AB5: =IFERROR(ROUNDDOWN(+AF5/(AC5*3.6),0)," ") -> 85 | AC5: 24 | AD5: 5049069 | AE5: 5056413 | AF5: =IFERROR((AE5-AD5)," ") -> 7344 | AG5: 20 | AH5: 24 | AK5: =IF(OR(AH5="",AG5=""),"",AH5*AG5*3.6) -> 1728 | AL5: =+BDFUENTES[[#This Row],[PZ CHB m3/día]]/3.6/BDFUENTES[[#This Row],[PZ CHB Horas Activo]] -> 38.225309 | AM5: 18 | AN5: 3509686 | AO5: 3512163 | AP5: =IFERROR((AO5-AN5)," ") -> 2477 | AR5: =IFERROR(+AU5/(AQ5*3.6)," ") | AS5: =IF(AT5>0,#REF!," ") | AU5: =IFERROR((AT5-AS5)," ") | AV5: =+BDFUENTES[[#This Row],[PZ TM m3/día]]/3.6/BDFUENTES[[#This Row],[PZ TM Horas Activo]] -> 11.296296 | AW5: 15 | AX5: 564606 | AY5: 565216 | AZ5: =IFERROR((AY5-AX5)," ") -> 610 | BA5: 125 | BB5: =IFERROR(+BE5/(BA5*3.6)," ") -> 4.3111111 | BC5: 5867299 | BD5: 5869239 | BE5: =IFERROR((BD5-BC5)," ") -> 1940 | BF5: 20 | BG5: =IFERROR(+BJ5/(BF5*3.6)," ") -> 17.888889 | BH5: 1526369 | BI5: 1527657 | BJ5: =IFERROR((BI5-BH5)," ") -> 1288 | BK5: 70 | BL5: =IFERROR(+BO5/(BK5*3.6)," ") -> 17.111111 | BM5: 6105110 | BN5: 6109422 | BO5: =IFERROR((BN5-BM5)," ") -> 4312
A6: =MONTH(B6) -> 1 | B6: 46024 | C6: 38 | D6: =IFERROR(+G6/(C6*3.6)," ") -> 13.333333 | E6: =IF(F6>0,F5," ") -> 3737755 | F6: 3739579 | G6: =IFERROR((F6-E6)," ") -> 1824 | H6: 25 | I6: =IFERROR(+L6/(H6*3.6)," ") -> 0 | J6: =IF(K6>0,K5," ") -> 1970853 | K6: 1970853 | L6: =IFERROR((K6-J6)," ") -> 0 | M6: 38 | N6: =IFERROR(+Q6/(M6*3.6)," ") -> 0 | O6: =IF(P6>0,P5," ") -> 414403 | P6: 414403 | Q6: =IFERROR((P6-O6)," ") -> 0 | R6: =+BDFUENTES[[#This Row],[PZ MED m3/día]]/3.6/BDFUENTES[[#This Row],[PZ MED Horas Activo]] -> 27.156863 | S6: 17 | T6: =IF(U6>0,U5," ") -> 229823 | U6: 231485 | V6: =IFERROR((U6-T6)," ") -> 1662 | W6: =IFERROR((AA6/X6)/3.6," ") -> 368.39372 | X6: 23 | Y6: =IF(Z6>0,Z5," ") -> 653820 | Z6: 685985 | AA6: =IFERROR((Z6-Y6)," ")-1662 -> 30503 | AB6: =IFERROR(ROUNDDOWN(+AF6/(AC6*3.6),0)," ") -> 91 | AC6: 24 | AD6: =IF(AE6>0,AE5," ") -> 5056413 | AE6: 5064297 | AF6: =IFERROR((AE6-AD6)," ") -> 7884 | AG6: 20 | AH6: 24 | AK6: =IF(OR(AH6="",AG6=""),"",AH6*AG6*3.6) -> 1728 | AL6: =+BDFUENTES[[#This Row],[PZ CHB m3/día]]/3.6/BDFUENTES[[#This Row],[PZ CHB Horas Activo]] -> 37.810458 | AM6: 17 | AN6: =IF(AO6>0,AO5," ") -> 3512163 | AO6: 3514477 | AP6: =IFERROR((AO6-AN6)," ") -> 2314 | AR6: =IFERROR(+AU6/(AQ6*3.6)," ") | AS6: =IF(AT6>0,#REF!," ") | AU6: =IFERROR((AT6-AS6)," ") | AV6: =+BDFUENTES[[#This Row],[PZ TM m3/día]]/3.6/BDFUENTES[[#This Row],[PZ TM Horas Activo]] -> 10.666667 | AW6: 15 | AX6: =IF(AY6>0,AY5," ") -> 565216 | AY6: 565792 | AZ6: =IFERROR((AY6-AX6)," ") -> 576 | BA6: 125 | BB6: =IFERROR(+BE6/(BA6*3.6)," ") -> 4.1977778 | BC6: =IF(BD6>0,BD5," ") -> 5869239 | BD6: 5871128 | BE6: =IFERROR((BD6-BC6)," ") -> 1889 | BF6: 20 | BG6: =IFERROR(+BJ6/(BF6*3.6)," ") -> 17.402778 | BH6: =IF(BI6>0,BI5," ") -> 1527657 | BI6: 1528910 | BJ6: =IFERROR((BI6-BH6)," ") -> 1253 | BK6: 70 | BL6: =IFERROR(+BO6/(BK6*3.6)," ") -> 13.813492 | BM6: =IF(BN6>0,BN5," ") -> 6109422 | BN6: 6112903 | BO6: =IFERROR((BN6-BM6)," ") -> 3481
A7: =MONTH(B7) -> 1 | B7: 46025 | C7: 38 | D7: =IFERROR(+G7/(C7*3.6)," ") -> 13.150585 | E7: =IF(F7>0,F6," ") -> 3739579 | F7: 3741378 | G7: =IFERROR((F7-E7)," ") -> 1799 | H7: 25 | I7: =IFERROR(+L7/(H7*3.6)," ") -> 0 | J7: =IF(K7>0,K6," ") -> 1970853 | K7: 1970853 | L7: =IFERROR((K7-J7)," ") -> 0 | M7: 38 | N7: =IFERROR(+Q7/(M7*3.6)," ") -> 0 | O7: =IF(P7>0,P6," ") -> 414403 | P7: 414403 | Q7: =IFERROR((P7-O7)," ") -> 0 | R7: =+BDFUENTES[[#This Row],[PZ MED m3/día]]/3.6/BDFUENTES[[#This Row],[PZ MED Horas Activo]] -> 27.631579 | S7: 3.8 | T7: =IF(U7>0,U6," ") -> 231485 | U7: 231863 | V7: =IFERROR((U7-T7)," ") -> 378 | W7: =IFERROR((AA7/X7)/3.6," ") -> 446.74769 | X7: 24 | Y7: =IF(Z7>0,Z6," ") -> 685985 | Z7: 724962 | AA7: =IFERROR((Z7-Y7)," ")-378 -> 38599 | AB7: =IFERROR(ROUNDDOWN(+AF7/(AC7*3.6),0)," ") -> 85 | AC7: 24 | AD7: =IF(AE7>0,AE6," ") -> 5064297 | AE7: 5071665 | AF7: =IFERROR((AE7-AD7)," ") -> 7368 | AG7: 20 | AH7: 24 | AK7: =IF(OR(AH7="",AG7=""),"",AH7*AG7*3.6) -> 1728 | AL7: =+BDFUENTES[[#This Row],[PZ CHB m3/día]]/3.6/BDFUENTES[[#This Row],[PZ CHB Horas Activo]] -> 36.857639 | AM7: 16 | AN7: =IF(AO7>0,AO6," ") -> 3514477 | AO7: 3516600 | AP7: =IFERROR((AO7-AN7)," ") -> 2123 | AR7: =IFERROR(+AU7/(AQ7*3.6)," ") | AS7: =IF(AT7>0,#REF!," ") | AU7: =IFERROR((AT7-AS7)," ") | AV7: =+BDFUENTES[[#This Row],[PZ TM m3/día]]/3.6/BDFUENTES[[#This Row],[PZ TM Horas Activo]] -> 11.148148 | AW7: 15 | AX7: =IF(AY7>0,AY6," ") -> 565792 | AY7: 566394 | AZ7: =IFERROR((AY7-AX7)," ") -> 602 | BA7: 125 | BB7: =IFERROR(+BE7/(BA7*3.6)," ") -> 3.9733333 | BC7: =IF(BD7>0,BD6," ") -> 5871128 | BD7: 5872916 | BE7: =IFERROR((BD7-BC7)," ") -> 1788 | BF7: 20 | BG7: =IFERROR(+BJ7/(BF7*3.6)," ") -> 18.083333 | BH7: =IF(BI7>0,BI6," ") -> 1528910 | BI7: 1530212 | BJ7: =IFERROR((BI7-BH7)," ") -> 1302 | BK7: 70 | BL7: =IFERROR(+BO7/(BK7*3.6)," ") -> 18.503968 | BM7: =IF(BN7>0,BN6," ") -> 6112903 | BN7: 6117566 | BO7: =IFERROR((BN7-BM7)," ") -> 4663
A8: =MONTH(B8) -> 1 | B8: 46026 | C8: 38 | D8: =IFERROR(+G8/(C8*3.6)," ") -> 13.311404 | E8: =IF(F8>0,F7," ") -> 3741378 | F8: 3743199 | G8: =IFERROR((F8-E8)," ") -> 1821 | H8: 25 | I8: =IFERROR(+L8/(H8*3.6)," ") -> 0 | J8: =IF(K8>0,K7," ") -> 1970853 | K8: 1970853 | L8: =IFERROR((K8-J8)," ") -> 0 | M8: 38 | N8: =IFERROR(+Q8/(M8*3.6)," ") -> 0 | O8: =IF(P8>0,P7," ") -> 414403 | P8: 414403 | Q8: =IFERROR((P8-O8)," ") -> 0 | R8: 0 | S8: 0 | T8: =IF(U8>0,U7," ") -> 231863 | U8: 231863 | V8: =IFERROR((U8-T8)," ") -> 0 | W8: =IFERROR((AA8/X8)/3.6," ") -> 454.0162 | X8: 24 | Y8: =IF(Z8>0,Z7," ") -> 724962 | Z8: 764189 | AA8: =IFERROR((Z8-Y8)," ") -> 39227 | AB8: =IFERROR(ROUNDDOWN(+AF8/(AC8*3.6),0)," ") -> 79 | AC8: 24 | AD8: =IF(AE8>0,AE7," ") -> 5071665 | AE8: 5078571 | AF8: =IFERROR((AE8-AD8)," ") -> 6906 | AG8: 20 | AH8: 24 | AK8: =IF(OR(AH8="",AG8=""),"",AH8*AG8*3.6) -> 1728 | AL8: =+BDFUENTES[[#This Row],[PZ CHB m3/día]]/3.6/BDFUENTES[[#This Row],[PZ CHB Horas Activo]] -> 38.839869 | AM8: 17 | AN8: =IF(AO8>0,AO7," ") -> 3516600 | AO8: 3518977 | AP8: =IFERROR((AO8-AN8)," ") -> 2377 | AR8: =IFERROR(+AU8/(AQ8*3.6)," ") | AS8: =IF(AT8>0,#REF!," ") | AU8: =IFERROR((AT8-AS8)," ") | AV8: =+BDFUENTES[[#This Row],[PZ TM m3/día]]/3.6/BDFUENTES[[#This Row],[PZ TM Horas Activo]] -> 10.074074 | AW8: 15 | AX8: =IF(AY8>0,AY7," ") -> 566394 | AY8: 566938 | AZ8: =IFERROR((AY8-AX8)," ") -> 544 | BA8: 125 | BB8: =IFERROR(+BE8/(BA8*3.6)," ") -> 4.0555556 | BC8: =IF(BD8>0,BD7," ") -> 5872916 | BD8: 5874741 | BE8: =IFERROR((BD8-BC8)," ") -> 1825 | BF8: 20 | BG8: =IFERROR(+BJ8/(BF8*3.6)," ") -> 18.638889 | BH8: =IF(BI8>0,BI7," ") -> 1530212 | BI8: 1531554 | BJ8: =IFERROR((BI8-BH8)," ") -> 1342 | BK8: 70 | BL8: =IFERROR(+BO8/(BK8*3.6)," ") -> 16.281746 | BM8: =IF(BN8>0,BN7," ") -> 6117566 | BN8: 6121669 | BO8: =IFERROR((BN8-BM8)," ") -> 4103
A9: =MONTH(B9) -> 1 | B9: 46027 | C9: 38 | D9: =IFERROR(+G9/(C9*3.6)," ") -> 13.362573 | E9: =IF(F9>0,F8," ") -> 3743199 | F9: 3745027 | G9: =IFERROR((F9-E9)," ") -> 1828 | H9: 25 | I9: =IFERROR(+L9/(H9*3.6)," ") -> 0 | J9: =IF(K9>0,K8," ") -> 1970853 | K9: 1970853 | L9: =IFERROR((K9-J9)," ") -> 0 | M9: 38 | N9: =IFERROR(+Q9/(M9*3.6)," ") -> 0 | O9: =IF(P9>0,P8," ") -> 414403 | P9: 414403 | Q9: =IFERROR((P9-O9)," ") -> 0 | R9: 0 | S9: 0 | T9: =IF(U9>0,U8," ") -> 231863 | U9: 231990 | V9: =IFERROR((U9-T9)," ") -> 127 | W9: =IFERROR((AA9/X9)/3.6," ") -> 454.91898 | X9: 24 | Y9: =IF(Z9>0,Z8," ") -> 764189 | Z9: 803621 | AA9: =IFERROR((Z9-Y9)," ")-127 -> 39305 | AB9: =IFERROR(ROUNDDOWN(+AF9/(AC9*3.6),0)," ") -> 77 | AC9: 24 | AD9: =IF(AE9>0,AE8," ") -> 5078571 | AE9: 5085283 | AF9: =IFERROR((AE9-AD9)," ") -> 6712 | AG9: 20 | AH9: 24 | AK9: =IF(OR(AH9="",AG9=""),"",AH9*AG9*3.6) -> 1728 | AL9: =+BDFUENTES[[#This Row],[PZ CHB m3/día]]/3.6/BDFUENTES[[#This Row],[PZ CHB Horas Activo]] -> 38.496732 | AM9: 17 | AN9: =IF(AO9>0,AO8," ") -> 3518977 | AO9: 3521333 | AP9: =IFERROR((AO9-AN9)," ") -> 2356 | AR9: =IFERROR(+AU9/(AQ9*3.6)," ") | AS9: =IF(AT9>0,AT8," ") | AU9: =IFERROR((AT9-AS9)," ") | AV9: =+BDFUENTES[[#This Row],[PZ TM m3/día]]/3.6/BDFUENTES[[#This Row],[PZ TM Horas Activo]] -> 11.458333 | AW9: 16 | AX9: =IF(AY9>0,AY8," ") -> 566938 | AY9: 567598 | AZ9: =IFERROR((AY9-AX9)," ") -> 660 | BA9: 125 | BB9: =IFERROR(+BE9/(BA9*3.6)," ") -> 4.3822222 | BC9: =IF(BD9>0,BD8," ") -> 5874741 | BD9: 5876713 | BE9: =IFERROR((BD9-BC9)," ") -> 1972 | BF9: 20 | BG9: =IFERROR(+BJ9/(BF9*3.6)," ") -> 16.152778 | BH9: =IF(BI9>0,BI8," ") -> 1531554 | BI9: 1532717 | BJ9: =IFERROR((BI9-BH9)," ") -> 1163 | BK9: 70 | BL9: =IFERROR(+BO9/(BK9*3.6)," ") -> 19.31746 | BM9: =IF(BN9>0,BN8," ") -> 6121669 | BN9: 6126537 | BO9: =IFERROR((BN9-BM9)," ") -> 4868
A10: =MONTH(B10) -> 1 | B10: 46028 | C10: 38 | D10: =IFERROR(+G10/(C10*3.6)," ") -> 13.421053 | E10: =IF(F10>0,F9," ") -> 3745027 | F10: 3746863 | G10: =IFERROR((F10-E10)," ") -> 1836 | H10: 25 | I10: =IFERROR(+L10/(H10*3.6)," ") -> 0 | J10: =IF(K10>0,K9," ") -> 1970853 | K10: 1970853 | L10: =IFERROR((K10-J10)," ") -> 0 | M10: 38 | N10: =IFERROR(+Q10/(M10*3.6)," ") -> 0 | O10: =IF(P10>0,P9," ") -> 414403 | P10: 414403 | Q10: =IFERROR((P10-O10)," ") -> 0 | R10: 0 | S10: 0 | T10: =IF(U10>0,U9," ") -> 231990 | U10: 231990 | V10: =IFERROR((U10-T10)," ") -> 0 | W10: =IFERROR((AA10/X10)/3.6," ") -> 416.35417 | X10: 24 | Y10: =IF(Z10>0,Z9," ") -> 803621 | Z10: 839594 | AA10: =IFERROR((Z10-Y10)," ") -> 35973 | AB10: =IFERROR(ROUNDDOWN(+AF10/(AC10*3.6),0)," ") -> 77 | AC10: 24 | AD10: =IF(AE10>0,AE9," ") -> 5085283 | AE10: 5091948 | AF10: =IFERROR((AE10-AD10)," ") -> 6665 | AG10: 20 | AH10: 24 | AK10: =IF(OR(AH10="",AG10=""),"",AH10*AG10*3.6) -> 1728 | AL10: =+BDFUENTES[[#This Row],[PZ CHB m3/día]]/3.6/BDFUENTES[[#This Row],[PZ CHB Horas Activo]] -> 39.526144 | AM10: 17 | AN10: =IF(AO10>0,AO9," ") -> 3521333 | AO10: 3523752 | AP10: =IFERROR((AO10-AN10)," ") -> 2419 | AR10: =IFERROR(+AU10/(AQ10*3.6)," ") | AS10: =IF(AT10>0,AT9," ") | AU10: =IFERROR((AT10-AS10)," ") | AV10: =+BDFUENTES[[#This Row],[PZ TM m3/día]]/3.6/BDFUENTES[[#This Row],[PZ TM Horas Activo]] -> 11.092593 | AW10: 15 | AX10: =IF(AY10>0,AY9," ") -> 567598 | AY10: 568197 | AZ10: =IFERROR((AY10-AX10)," ") -> 599 | BA10: 125 | BB10: =IFERROR(+BE10/(BA10*3.6)," ") -> 4.2644444 | BC10: =IF(BD10>0,BD9," ") -> 5876713 | BD10: 5878632 | BE10: =IFERROR((BD10-BC10)," ") -> 1919 | BF10: 20 | BG10: =IFERROR(+BJ10/(BF10*3.6)," ") -> 17.375 | BH10: =IF(BI10>0,BI9," ") -> 1532717 | BI10: 1533968 | BJ10: =IFERROR((BI10-BH10)," ") -> 1251 | BK10: 70 | BL10: =IFERROR(+BO10/(BK10*3.6)," ") -> 16.662698 | BM10: =IF(BN10>0,BN9," ") -> 6126537 | BN10: 6130736 | BO10: =IFERROR((BN10-BM10)," ") -> 4199
A11: =MONTH(B11) -> 1 | B11: 46029 | C11: 38 | D11: =IFERROR(+G11/(C11*3.6)," ") -> 13.289474 | E11: =IF(F11>0,F10," ") -> 3746863 | F11: 3748681 | G11: =IFERROR((F11-E11)," ") -> 1818 | H11: 25 | I11: =IFERROR(+L11/(H11*3.6)," ") -> 0 | J11: =IF(K11>0,K10," ") -> 1970853 | K11: 1970853 | L11: =IFERROR((K11-J11)," ") -> 0 | M11: 38 | N11: =IFERROR(+Q11/(M11*3.6)," ") -> 0 | O11: =IF(P11>0,P10," ") -> 414403 | P11: 414403 | Q11: =IFERROR((P11-O11)," ") -> 0 | R11: 0 | S11: 0 | T11: =IF(U11>0,U10," ") -> 231990 | U11: 232061 | V11: 0 | W11: =IFERROR((AA11/X11)/3.6," ") -> 432.96296 | X11: 24 | Y11: =IF(Z11>0,Z10," ") -> 839594 | Z11: 877002 | AA11: =IFERROR((Z11-Y11)," ") -> 37408 | AB11: =IFERROR(ROUNDDOWN(+AF11/(AC11*3.6),0)," ") -> 77 | AC11: 24 | AD11: =IF(AE11>0,AE10," ") -> 5091948 | AE11: 5098663 | AF11: =IFERROR((AE11-AD11)," ") -> 6715 | AG11: 20 | AH11: 24 | AK11: =IF(OR(AH11="",AG11=""),"",AH11*AG11*3.6) -> 1728 | AL11: =+BDFUENTES[[#This Row],[PZ CHB m3/día]]/3.6/BDFUENTES[[#This Row],[PZ CHB Horas Activo]] -> 39.068627 | AM11: 17 | AN11: =IF(AO11>0,AO10," ") -> 3523752 | AO11: 3526143 | AP11: =IFERROR((AO11-AN11)," ") -> 2391 | AR11: =IFERROR(+AU11/(AQ11*3.6)," ") | AS11: =IF(AT11>0,AT10," ") | AU11: =IFERROR((AT11-AS11)," ") | AV11: =+BDFUENTES[[#This Row],[PZ TM m3/día]]/3.6/BDFUENTES[[#This Row],[PZ TM Horas Activo]] -> 11.277778 | AW11: 15 | AX11: =IF(AY11>0,AY10," ") -> 568197 | AY11: 568806 | AZ11: =IFERROR((AY11-AX11)," ") -> 609 | BA11: 125 | BB11: =IFERROR(+BE11/(BA11*3.6)," ") -> 4.12 | BC11: =IF(BD11>0,BD10," ") -> 5878632 | BD11: 5880486 | BE11: =IFERROR((BD11-BC11)," ") -> 1854 | BF11: 20 | BG11: =IFERROR(+BJ11/(BF11*3.6)," ") -> 17.638889 | BH11: =IF(BI11>0,BI10," ") -> 1533968 | BI11: 1535238 | BJ11: =IFERROR((BI11-BH11)," ") -> 1270 | BK11: 70 | BL11: =IFERROR(+BO11/(BK11*3.6)," ") -> 18.936508 | BM11: =IF(BN11>0,BN10," ") -> 6130736 | BN11: 6135508 | BO11: =IFERROR((BN11-BM11)," ") -> 4772
A12: =MONTH(B12) -> 1 | B12: 46030 | C12: 38 | D12: =IFERROR(+G12/(C12*3.6)," ") -> 13.450292 | E12: =IF(F12>0,F11," ") -> 3748681 | F12: 3750521 | G12: =IFERROR((F12-E12)," ") -> 1840 | H12: 25 | I12: =IFERROR(+L12/(H12*3.6)," ") -> 0 | J12: =IF(K12>0,K11," ") -> 1970853 | K12: 1970853 | L12: =IFERROR((K12-J12)," ") -> 0 | M12: 38 | N12: =IFERROR(+Q12/(M12*3.6)," ") -> 0 | O12: =IF(P12>0,P11," ") -> 414403 | P12: 414403 | Q12: =IFERROR((P12-O12)," ") -> 0 | R12: 0 | S12: 0 | T12: =IF(U12>0,U11," ") -> 232061 | U12: 232133 | V12: 0 | W12: =IFERROR((AA12/X12)/3.6," ") -> 463.61263 | X12: 24 | Y12: =IF(Z12>0,Z11," ") -> 877002 | Z12: 917058.13 | AA12: =IFERROR((Z12-Y12)," ") -> 40056.131 | AB12: =IFERROR(ROUNDDOWN(+AF12/(AC12*3.6),0)," ") -> 79 | AC12: 24 | AD12: =IF(AE12>0,AE11," ") -> 5098663 | AE12: 5105497 | AF12: =IFERROR((AE12-AD12)," ") -> 6834 | AG12: 20 | AH12: 24 | AK12: =IF(OR(AH12="",AG12=""),"",AH12*AG12*3.6) -> 1728 | AL12: =+BDFUENTES[[#This Row],[PZ CHB m3/día]]/3.6/BDFUENTES[[#This Row],[PZ CHB Horas Activo]] -> 39.243827 | AM12: 18 | AN12: =IF(AO12>0,AO11," ") -> 3526143 | AO12: 3528686 | AP12: =IFERROR((AO12-AN12)," ") -> 2543 | AR12: =IFERROR(+AU12/(AQ12*3.6)," ") | AS12: =IF(AT12>0,AT11," ") | AU12: =IFERROR((AT12-AS12)," ") | AV12: =+BDFUENTES[[#This Row],[PZ TM m3/día]]/3.6/BDFUENTES[[#This Row],[PZ TM Horas Activo]] -> 11.333333 | AW12: 15 | AX12: =IF(AY12>0,AY11," ") -> 568806 | AY12: 569418 | AZ12: =IFERROR((AY12-AX12)," ") -> 612 | BA12: 125 | BB12: =IFERROR(+BE12/(BA12*3.6)," ") -> 4.2866667 | BC12: =IF(BD12>0,BD11," ") -> 5880486 | BD12: 5882415 | BE12: =IFERROR((BD12-BC12)," ") -> 1929 | BF12: 20 | BG12: =IFERROR(+BJ12/(BF12*3.6)," ") -> 17.902778 | BH12: =IF(BI12>0,BI11," ") -> 1535238 | BI12: 1536527 | BJ12: =IFERROR((BI12-BH12)," ") -> 1289 | BK12: 70 | BL12: =IFERROR(+BO12/(BK12*3.6)," ") -> 17.075397 | BM12: =IF(BN12>0,BN11," ") -> 6135508 | BN12: 6139811 | BO12: =IFERROR((BN12-BM12)," ") -> 4303
A13: =MONTH(B13) -> 1 | B13: 46031 | C13: 38 | D13: =IFERROR(+G13/(C13*3.6)," ") -> 13.267544 | E13: =IF(F13>0,F12," ") -> 3750521 | F13: 3752336 | G13: =IFERROR((F13-E13)," ") -> 1815 | H13: 25 | I13: =IFERROR(+L13/(H13*3.6)," ") -> 0 | J13: =IF(K13>0,K12," ") -> 1970853 | K13: 1970853 | L13: =IFERROR((K13-J13)," ") -> 0 | M13: 38 | N13: =IFERROR(+Q13/(M13*3.6)," ") -> 0 | O13: =IF(P13>0,P12," ") -> 414403 | P13: 414403 | Q13: =IFERROR((P13-O13)," ") -> 0 | R13: 0 | S13: 0 | T13: =IF(U13>0,U12," ") -> 232133 | U13: 232172 | V13: 0 | W13: =IFERROR((AA13/X13)/3.6," ") -> 431.36422 | X13: 24 | Y13: =IF(Z13>0,Z12," ") -> 917058.13 | Z13: 954328 | AA13: =IFERROR((Z13-Y13)," ") -> 37269.869 | AB13: =IFERROR(ROUNDDOWN(+AF13/(AC13*3.6),0)," ") -> 83 | AC13: 24 | AD13: =IF(AE13>0,AE12," ") -> 5105497 | AE13: 5112705 | AF13: =IFERROR((AE13-AD13)," ") -> 7208 | AG13: 20 | AH13: 24 | AK13: =IF(OR(AH13="",AG13=""),"",AH13*AG13*3.6) -> 1728 | AL13: =+BDFUENTES[[#This Row],[PZ CHB m3/día]]/3.6/BDFUENTES[[#This Row],[PZ CHB Horas Activo]] -> 38.564815 | AM13: 18 | AN13: =IF(AO13>0,AO12," ") -> 3528686 | AO13: 3531185 | AP13: =IFERROR((AO13-AN13)," ") -> 2499 | AR13: =IFERROR(+AU13/(AQ13*3.6)," ") | AS13: =IF(AT13>0,AT12," ") | AU13: =IFERROR((AT13-AS13)," ") | AV13: =+BDFUENTES[[#This Row],[PZ TM m3/día]]/3.6/BDFUENTES[[#This Row],[PZ TM Horas Activo]] -> 11.777778 | AW13: 15 | AX13: =IF(AY13>0,AY12," ") -> 569418 | AY13: 570054 | AZ13: =IFERROR((AY13-AX13)," ") -> 636 | BA13: 125 | BB13: =IFERROR(+BE13/(BA13*3.6)," ") -> 4.0955556 | BC13: =IF(BD13>0,BD12," ") -> 5882415 | BD13: 5884258 | BE13: =IFERROR((BD13-BC13)," ") -> 1843 | BF13: 20 | BG13: =IFERROR(+BJ13/(BF13*3.6)," ") -> 15.694444 | BH13: =IF(BI13>0,BI12," ") -> 1536527 | BI13: =1537801-20*3.6*2 -> 1537657 | BJ13: =IFERROR((BI13-BH13)," ") -> 1130 | BK13: 70 | BL13: =IFERROR(+BO13/(BK13*3.6)," ") -> 19.25 | BM13: =IF(BN13>0,BN12," ") -> 6139811 | BN13: 6144662 | BO13: =IFERROR((BN13-BM13)," ") -> 4851
A14: =MONTH(B14) -> 1 | B14: 46032 | C14: 38 | D14: =IFERROR(+G14/(C14*3.6)," ") -> 19.064327 | E14: =IF(F14>0,F13," ") -> 3752336 | F14: 3754944 | G14: =IFERROR((F14-E14)," ") -> 2608 | H14: 25 | I14: =IFERROR(+L14/(H14*3.6)," ") -> 0 | J14: =IF(K14>0,K13," ") -> 1970853 | K14: 1970853 | L14: =IFERROR((K14-J14)," ") -> 0 | M14: 38 | N14: =IFERROR(+Q14/(M14*3.6)," ") -> 0 | O14: =IF(P14>0,P13," ") -> 414403 | P14: 414403 | Q14: =IFERROR((P14-O14)," ") -> 0 | R14: =+BDFUENTES[[#This Row],[PZ MED m3/día]]/3.6/BDFUENTES[[#This Row],[PZ MED Horas Activo]] -> 27.972222 | S14: 10 | T14: =IF(U14>0,U13," ") -> 232172 | U14: 233179 | V14: =IFERROR((U14-T14)," ") -> 1007 | W14: =IFERROR((AA14/X14)/3.6," ") -> 383.72685 | X14: 24 | Y14: =IF(Z14>0,Z13," ") -> 954328 | Z14: 988489 | AA14: =IFERROR((Z14-Y14)," ")-1007 -> 33154 | AB14: =IFERROR(ROUNDDOWN(+AF14/(AC14*3.6),0)," ") -> 58 | AC14: 24 | AD14: =IF(AE14>0,AE13," ") -> 5112705 | AE14: 5117791 | AF14: =IFERROR((AE14-AD14)," ") -> 5086 | AG14: 20 | AH14: 24 | AK14: =IF(OR(AH14="",AG14=""),"",AH14*AG14*3.6) -> 1728 | AL14: =+BDFUENTES[[#This Row],[PZ CHB m3/día]]/3.6/BDFUENTES[[#This Row],[PZ CHB Horas Activo]] -> 38.225309 | AM14: 18 | AN14: =IF(AO14>0,AO13," ") -> 3531185 | AO14: 3533662 | AP14: =IFERROR((AO14-AN14)," ") -> 2477 | AR14: =IFERROR(+AU14/(AQ14*3.6)," ") | AS14: =IF(AT14>0,AT13," ") | AU14: =IFERROR((AT14-AS14)," ") | AV14: =+BDFUENTES[[#This Row],[PZ TM m3/día]]/3.6/BDFUENTES[[#This Row],[PZ TM Horas Activo]] -> 11.222222 | AW14: 15 | AX14: =IF(AY14>0,AY13," ") -> 570054 | AY14: 570660 | AZ14: =IFERROR((AY14-AX14)," ") -> 606 | BA14: 125 | BB14: =IFERROR(+BE14/(BA14*3.6)," ") -> 5.9466667 | BC14: =IF(BD14>0,BD13," ") -> 5884258 | BD14: 5886934 | BE14: =IFERROR((BD14-BC14)," ") -> 2676 | BF14: 20 | BG14: =IFERROR(+BJ14/(BF14*3.6)," ") -> 18.388889 | BH14: =IF(BI14>0,BI13," ") -> 1537657 | BI14: 1538981 | BJ14: =IFERROR((BI14-BH14)," ") -> 1324 | BK14: 70 | BL14: =IFERROR(+BO14/(BK14*3.6)," ") -> 17.146825 | BM14: =IF(BN14>0,BN13," ") -> 6144662 | BN14: 6148983 | BO14: =IFERROR((BN14-BM14)," ") -> 4321
A15: =MONTH(B15) -> 1 | B15: 46033 | C15: 38 | D15: =IFERROR(+G15/(C15*3.6)," ") -> 13.311404 | E15: =IF(F15>0,F14," ") -> 3754944 | F15: 3756765 | G15: =IFERROR((F15-E15)," ") -> 1821 | H15: 25 | I15: =IFERROR(+L15/(H15*3.6)," ") -> 0 | J15: =IF(K15>0,K14," ") -> 1970853 | K15: 1970853 | L15: =IFERROR((K15-J15)," ") -> 0 | M15: 38 | N15: =IFERROR(+Q15/(M15*3.6)," ") -> 0 | O15: =IF(P15>0,P14," ") -> 414403 | P15: 414403 | Q15: =IFERROR((P15-O15)," ") -> 0 | R15: =+BDFUENTES[[#This Row],[PZ MED m3/día]]/3.6/BDFUENTES[[#This Row],[PZ MED Horas Activo]] -> 29.411765 | S15: 17 | T15: =IF(U15>0,U14," ") -> 233179 | U15: 234979 | V15: =IFERROR((U15-T15)," ") -> 1800 | W15: =IFERROR((AA15/X15)/3.6," ") -> 360.19676 | X15: 24 | Y15: =IF(Z15>0,Z14," ") -> 988489 | Z15: 1021410 | AA15: =IFERROR((Z15-Y15)," ")-1800 -> 31121 | AB15: =IFERROR(ROUNDDOWN(+AF15/(AC15*3.6),0)," ") -> 73 | AC15: 24 | AD15: =IF(AE15>0,AE14," ") -> 5117791 | AE15: 5124148 | AF15: =IFERROR((AE15-AD15)," ") -> 6357 | AG15: 20 | AH15: 24 | AK15: =IF(OR(AH15="",AG15=""),"",AH15*AG15*3.6) -> 1728 | AL15: =+BDFUENTES[[#This Row],[PZ CHB m3/día]]/3.6/BDFUENTES[[#This Row],[PZ CHB Horas Activo]] -> 38.011696 | AM15: 19 | AN15: =IF(AO15>0,AO14," ") -> 3533662 | AO15: 3536262 | AP15: =IFERROR((AO15-AN15)," ") -> 2600 | AR15: =IFERROR(+AU15/(AQ15*3.6)," ") | AS15: =IF(AT15>0,AT14," ") | AU15: =IFERROR((AT15-AS15)," ") | AV15: =+BDFUENTES[[#This Row],[PZ TM m3/día]]/3.6/BDFUENTES[[#This Row],[PZ TM Horas Activo]] -> 11.259259 | AW15: 15 | AX15: =IF(AY15>0,AY14," ") -> 570660 | AY15: 571268 | AZ15: =IFERROR((AY15-AX15)," ") -> 608 | BA15: 125 | BB15: =IFERROR(+BE15/(BA15*3.6)," ") -> 4.1222222 | BC15: =IF(BD15>0,BD14," ") -> 5886934 | BD15: 5888789 | BE15: =IFERROR((BD15-BC15)," ") -> 1855 | BF15: 20 | BG15: =IFERROR(+BJ15/(BF15*3.6)," ") -> 17.583333 | BH15: =IF(BI15>0,BI14," ") -> 1538981 | BI15: 1540247 | BJ15: =IFERROR((BI15-BH15)," ") -> 1266 | BK15: 70 | BL15: =IFERROR(+BO15/(BK15*3.6)," ") -> 18.507937 | BM15: =IF(BN15>0,BN14," ") -> 6148983 | BN15: 6153647 | BO15: =IFERROR((BN15-BM15)," ") -> 4664
A16: =MONTH(B16) -> 1 | B16: 46034 | C16: 38 | D16: =IFERROR(+G16/(C16*3.6)," ") -> 13.486842 | E16: =IF(F16>0,F15," ") -> 3756765 | F16: 3758610 | G16: =IFERROR((F16-E16)," ") -> 1845 | H16: 25 | I16: =IFERROR(+L16/(H16*3.6)," ") -> 0 | J16: =IF(K16>0,K15," ") -> 1970853 | K16: 1970853 | L16: =IFERROR((K16-J16)," ") -> 0 | M16: 38 | N16: =IFERROR(+Q16/(M16*3.6)," ") -> 0 | O16: =IF(P16>0,P15," ") -> 414403 | P16: 414403 | Q16: =IFERROR((P16-O16)," ") -> 0 | R16: =+BDFUENTES[[#This Row],[PZ MED m3/día]]/3.6/BDFUENTES[[#This Row],[PZ MED Horas Activo]] -> 28.402778 | S16: 20 | T16: =IF(U16>0,U15," ") -> 234979 | U16: 237024 | V16: =IFERROR((U16-T16)," ") -> 2045 | W16: =IFERROR((AA16/X16)/3.6," ") -> 359.74569 | X16: 22 | Y16: =IF(Z16>0,Z15," ") -> 1021410 | Z16: 1051946.9 | AA16: =IFERROR((Z16-Y16)," ")-2045 -> 28491.859 | AB16: =IFERROR(ROUNDDOWN(+AF16/(AC16*3.6),0)," ") -> 76 | AC16: 24 | AD16: =IF(AE16>0,AE15," ") -> 5124148 | AE16: 5130715 | AF16: =IFERROR((AE16-AD16)," ") -> 6567 | AG16: 20 | AH16: 24 | AK16: =IF(OR(AH16="",AG16=""),"",AH16*AG16*3.6) -> 1728 | AL16: =+BDFUENTES[[#This Row],[PZ CHB m3/día]]/3.6/BDFUENTES[[#This Row],[PZ CHB Horas Activo]] -> 39.444444 | AM16: 17 | AN16: =IF(AO16>0,AO15," ") -> 3536262 | AO16: 3538676 | AP16: =IFERROR((AO16-AN16)," ") -> 2414 | AR16: =IFERROR(+AU16/(AQ16*3.6)," ") | AS16: =IF(AT16>0,AT15," ") | AU16: =IFERROR((AT16-AS16)," ") | AV16: =+BDFUENTES[[#This Row],[PZ TM m3/día]]/3.6/BDFUENTES[[#This Row],[PZ TM Horas Activo]] -> 11.592593 | AW16: 15 | AX16: =IF(AY16>0,AY15," ") -> 571268 | AY16: 571894 | AZ16: =IFERROR((AY16-AX16)," ") -> 626 | BA16: 125 | BB16: =IFERROR(+BE16/(BA16*3.6)," ") -> 4.2022222 | BC16: =IF(BD16>0,BD15," ") -> 5888789 | BD16: 5890680 | BE16: =IFERROR((BD16-BC16)," ") -> 1891 | BF16: 20 | BG16: =IFERROR(+BJ16/(BF16*3.6)," ") -> 13.25 | BH16: =IF(BI16>0,BI15," ") -> 1540247 | BI16: 1541201 | BJ16: =IFERROR((BI16-BH16)," ") -> 954 | BK16: 70 | BL16: =IFERROR(+BO16/(BK16*3.6)," ") -> 14.888889 | BM16: =IF(BN16>0,BN15," ") -> 6153647 | BN16: 6157399 | BO16: =IFERROR((BN16-BM16)," ") -> 3752
A17: =MONTH(B17) -> 1 | B17: 46035 | C17: 38 | D17: =IFERROR(+G17/(C17*3.6)," ") -> 13.450292 | E17: =IF(F17>0,F16," ") -> 3758610 | F17: 3760450 | G17: =IFERROR((F17-E17)," ") -> 1840 | H17: 25 | I17: =IFERROR(+L17/(H17*3.6)," ") -> 0 | J17: =IF(K17>0,K16," ") -> 1970853 | K17: 1970853 | L17: =IFERROR((K17-J17)," ") -> 0 | M17: 38 | N17: =IFERROR(+Q17/(M17*3.6)," ") -> 0 | O17: =IF(P17>0,P16," ") -> 414403 | P17: 414403 | Q17: =IFERROR((P17-O17)," ") -> 0 | R17: =+BDFUENTES[[#This Row],[PZ MED m3/día]]/3.6/BDFUENTES[[#This Row],[PZ MED Horas Activo]] -> 28.425926 | S17: 18 | T17: =IF(U17>0,U16," ") -> 237024 | U17: 238866 | V17: =IFERROR((U17-T17)," ") -> 1842 | W17: =IFERROR((AA17/X17)/3.6," ") -> 199.417 | X17: 24 | Y17: =IF(Z17>0,Z16," ") -> 1051946.9 | Z17: 1071018.5 | AA17: =IFERROR((Z17-Y17)," ")-1842 -> 17229.629 | AB17: =IFERROR(ROUNDDOWN(+AF17/(AC17*3.6),0)," ") -> 65 | AC17: 24 | AD17: =IF(AE17>0,AE16," ") -> 5130715 | AE17: 5136358 | AF17: =IFERROR((AE17-AD17)," ") -> 5643 | AG17: 20 | AH17: 24 | AK17: =IF(OR(AH17="",AG17=""),"",AH17*AG17*3.6) -> 1728 | AL17: =+BDFUENTES[[#This Row],[PZ CHB m3/día]]/3.6/BDFUENTES[[#This Row],[PZ CHB Horas Activo]] -> 38.395062 | AM17: 18 | AN17: =IF(AO17>0,AO16," ") -> 3538676 | AO17: 3541164 | AP17: =IFERROR((AO17-AN17)," ") -> 2488 | AR17: =IFERROR(+AU17/(AQ17*3.6)," ") | AS17: =IF(AT17>0,AT16," ") | AU17: =IFERROR((AT17-AS17)," ") | AV17: =+BDFUENTES[[#This Row],[PZ TM m3/día]]/3.6/BDFUENTES[[#This Row],[PZ TM Horas Activo]] -> 11.351852 | AW17: 15 | AX17: =IF(AY17>0,AY16," ") -> 571894 | AY17: 572507 | AZ17: =IFERROR((AY17-AX17)," ") -> 613 | BA17: 125 | BB17: =IFERROR(+BE17/(BA17*3.6)," ") -> 4.2044444 | BC17: =IF(BD17>0,BD16," ") -> 5890680 | BD17: 5892572 | BE17: =IFERROR((BD17-BC17)," ") -> 1892 | BF17: 20 | BG17: =IFERROR(+BJ17/(BF17*3.6)," ") -> 17.347222 | BH17: =IF(BI17>0,BI16," ") -> 1541201 | BI17: 1542450 | BJ17: =IFERROR((BI17-BH17)," ") -> 1249 | BK17: 70 | BL17: =IFERROR(+BO17/(BK17*3.6)," ") -> 6.765873 | BM17: =IF(BN17>0,BN16," ") -> 6157399 | BN17: 6159104 | BO17: =IFERROR((BN17-BM17)," ") -> 1705
A18: =MONTH(B18) -> 1 | B18: 46036 | C18: 38 | D18: =IFERROR(+G18/(C18*3.6)," ") -> 13.245614 | E18: =IF(F18>0,F17," ") -> 3760450 | F18: 3762262 | G18: =IFERROR((F18-E18)," ") -> 1812 | H18: 25 | I18: =IFERROR(+L18/(H18*3.6)," ") -> 0 | J18: =IF(K18>0,K17," ") -> 1970853 | K18: 1970853 | L18: =IFERROR((K18-J18)," ") -> 0 | M18: 38 | N18: =IFERROR(+Q18/(M18*3.6)," ") -> 0 | O18: =IF(P18>0,P17," ") -> 414403 | P18: 414403 | Q18: =IFERROR((P18-O18)," ") -> 0 | R18: =+BDFUENTES[[#This Row],[PZ MED m3/día]]/3.6/BDFUENTES[[#This Row],[PZ MED Horas Activo]] -> 27.401961 | S18: 17 | T18: =IF(U18>0,U17," ") -> 238866 | U18: 240543 | V18: =IFERROR((U18-T18)," ") -> 1677 | W18: =IFERROR((AA18/X18)/3.6," ") -> 281.48113 | X18: 24 | Y18: =IF(Z18>0,Z17," ") -> 1071018.5 | Z18: 1097015.5 | AA18: =IFERROR((Z18-Y18)," ")-1677 -> 24319.97 | AB18: =IFERROR(ROUNDDOWN(+AF18/(AC18*3.6),0)," ") -> 65 | AC18: 24 | AD18: =IF(AE18>0,AE17," ") -> 5136358 | AE18: 5141977 | AF18: =IFERROR((AE18-AD18)," ") -> 5619 | AG18: 20 | AH18: 24 | AK18: =IF(OR(AH18="",AG18=""),"",AH18*AG18*3.6) -> 1728 | AL18: =+BDFUENTES[[#This Row],[PZ CHB m3/día]]/3.6/BDFUENTES[[#This Row],[PZ CHB Horas Activo]] -> 38.117284 | AM18: 18 | AN18: =IF(AO18>0,AO17," ") -> 3541164 | AO18: 3543634 | AP18: =IFERROR((AO18-AN18)," ") -> 2470 | AR18: =IFERROR(+AU18/(AQ18*3.6)," ") | AS18: =IF(AT18>0,AT17," ") | AU18: =IFERROR((AT18-AS18)," ") | AV18: =+BDFUENTES[[#This Row],[PZ TM m3/día]]/3.6/BDFUENTES[[#This Row],[PZ TM Horas Activo]] -> 10.555556 | AW18: 14 | AX18: =IF(AY18>0,AY17," ") -> 572507 | AY18: 573039 | AZ18: =IFERROR((AY18-AX18)," ") -> 532 | BA18: 125 | BB18: =IFERROR(+BE18/(BA18*3.6)," ") -> 4.32 | BC18: =IF(BD18>0,BD17," ") -> 5892572 | BD18: 5894516 | BE18: =IFERROR((BD18-BC18)," ") -> 1944 | BF18: 20 | BG18: =IFERROR(+BJ18/(BF18*3.6)," ") -> 17.652778 | BH18: =IF(BI18>0,BI17," ") -> 1542450 | BI18: 1543721 | BJ18: =IFERROR((BI18-BH18)," ") -> 1271 | BK18: 70 | BL18: =IFERROR(+BO18/(BK18*3.6)," ") -> 12.103175 | BM18: =IF(BN18>0,BN17," ") -> 6159104 | BN18: 6162154 | BO18: =IFERROR((BN18-BM18)," ") -> 3050
A19: =MONTH(B19) -> 1 | B19: 46037 | C19: 38 | D19: =IFERROR(+G19/(C19*3.6)," ") -> 13.114035 | E19: =IF(F19>0,F18," ") -> 3762262 | F19: 3764056 | G19: =IFERROR((F19-E19)," ") -> 1794 | H19: 25 | I19: =IFERROR(+L19/(H19*3.6)," ") -> 0 | J19: =IF(K19>0,K18," ") -> 1970853 | K19: 1970853 | L19: =IFERROR((K19-J19)," ") -> 0 | M19: 38 | N19: =IFERROR(+Q19/(M19*3.6)," ") -> 1.8494152 | O19: =IF(P19>0,P18," ") -> 414403 | P19: 414656 | Q19: =IFERROR((P19-O19)," ") -> 253 | R19: =+BDFUENTES[[#This Row],[PZ MED m3/día]]/3.6/BDFUENTES[[#This Row],[PZ MED Horas Activo]] -> 27.222222 | S19: 13 | T19: =IF(U19>0,U18," ") -> 240543 | U19: 241817 | V19: =IFERROR((U19-T19)," ") -> 1274 | W19: =IFERROR((AA19/X19)/3.6," ") -> 268.5075 | X19: 24 | Y19: =IF(Z19>0,Z18," ") -> 1097015.5 | Z19: 1121488.5 | AA19: =IFERROR((Z19-Y19)," ")-1274 -> 23199.048 | AB19: =IFERROR(ROUNDDOWN(+AF19/(AC19*3.6),0)," ") -> 61 | AC19: 24 | AD19: =IF(AE19>0,AE18," ") -> 5141977 | AE19: 5147251 | AF19: =IFERROR((AE19-AD19)," ") -> 5274 | AG19: 20 | AH19: 24 | AK19: =IF(OR(AH19="",AG19=""),"",AH19*AG19*3.6) -> 1728 | AL19: =+BDFUENTES[[#This Row],[PZ CHB m3/día]]/3.6/BDFUENTES[[#This Row],[PZ CHB Horas Activo]] -> 37.962963 | AM19: 18 | AN19: =IF(AO19>0,AO18," ") -> 3543634 | AO19: 3546094 | AP19: =IFERROR((AO19-AN19)," ") -> 2460 | AR19: =IFERROR(+AU19/(AQ19*3.6)," ") | AS19: =IF(AT19>0,AT18," ") | AU19: =IFERROR((AT19-AS19)," ") | AV19: =+BDFUENTES[[#This Row],[PZ TM m3/día]]/3.6/BDFUENTES[[#This Row],[PZ TM Horas Activo]] -> 11.611111 | AW19: 15 | AX19: =IF(AY19>0,AY18," ") -> 573039 | AY19: 573666 | AZ19: =IFERROR((AY19-AX19)," ") -> 627 | BA19: 125 | BB19: =IFERROR(+BE19/(BA19*3.6)," ") -> 4.72 | BC19: =IF(BD19>0,BD18," ") -> 5894516 | BD19: 5896640 | BE19: =IFERROR((BD19-BC19)," ") -> 2124 | BF19: 20 | BG19: =IFERROR(+BJ19/(BF19*3.6)," ") -> 17.972222 | BH19: =IF(BI19>0,BI18," ") -> 1543721 | BI19: 1545015 | BJ19: =IFERROR((BI19-BH19)," ") -> 1294 | BK19: 70 | BL19: =IFERROR(+BO19/(BK19*3.6)," ") -> 11.392857 | BM19: =IF(BN19>0,BN18," ") -> 6162154 | BN19: 6165025 | BO19: =IFERROR((BN19-BM19)," ") -> 2871
A20: =MONTH(B20) -> 1 | B20: 46038 | C20: 38 | D20: =IFERROR(+G20/(C20*3.6)," ") -> 13.428363 | E20: =IF(F20>0,F19," ") -> 3764056 | F20: 3765893 | G20: =IFERROR((F20-E20)," ") -> 1837 | H20: 25 | I20: =IFERROR(+L20/(H20*3.6)," ") -> 0 | J20: =IF(K20>0,K19," ") -> 1970853 | K20: 1970853 | L20: =IFERROR((K20-J20)," ") -> 0 | M20: 38 | N20: =IFERROR(+Q20/(M20*3.6)," ") -> 0 | O20: =IF(P20>0,P19," ") -> 414656 | P20: 414656 | Q20: =IFERROR((P20-O20)," ") -> 0 | R20: =+BDFUENTES[[#This Row],[PZ MED m3/día]]/3.6/BDFUENTES[[#This Row],[PZ MED Horas Activo]] -> 28.300654 | S20: 17 | T20: =IF(U20>0,U19," ") -> 241817 | U20: 243549 | V20: =IFERROR((U20-T20)," ") -> 1732 | W20: =IFERROR((AA20/X20)/3.6," ") -> 305.31822 | X20: 24 | Y20: =IF(Z20>0,Z19," ") -> 1121488.5 | Z20: 1149600 | AA20: =IFERROR((Z20-Y20)," ")-1732 -> 26379.494 | AB20: =IFERROR(ROUNDDOWN(+AF20/(AC20*3.6),0)," ") -> 58 | AC20: 24 | AD20: =IF(AE20>0,AE19," ") -> 5147251 | AE20: 5152286 | AF20: =IFERROR((AE20-AD20)," ") -> 5035 | AG20: 20 | AH20: 24 | AK20: =IF(OR(AH20="",AG20=""),"",AH20*AG20*3.6) -> 1728 | AL20: =+BDFUENTES[[#This Row],[PZ CHB m3/día]]/3.6/BDFUENTES[[#This Row],[PZ CHB Horas Activo]] -> 38.72807 | AM20: 19 | AN20: =IF(AO20>0,AO19," ") -> 3546094 | AO20: 3548743 | AP20: =IFERROR((AO20-AN20)," ") -> 2649 | AR20: =IFERROR(+AU20/(AQ20*3.6)," ") | AS20: =IF(AT20>0,AT19," ") | AU20: =IFERROR((AT20-AS20)," ") | AV20: =+BDFUENTES[[#This Row],[PZ TM m3/día]]/3.6/BDFUENTES[[#This Row],[PZ TM Horas Activo]] -> 11.648148 | AW20: 15 | AX20: =IF(AY20>0,AY19," ") -> 573666 | AY20: 574295 | AZ20: =IFERROR((AY20-AX20)," ") -> 629 | BA20: 125 | BB20: =IFERROR(+BE20/(BA20*3.6)," ") -> 4.5111111 | BC20: =IF(BD20>0,BD19," ") -> 5896640 | BD20: 5898670 | BE20: =IFERROR((BD20-BC20)," ") -> 2030 | BF20: 20 | BG20: =IFERROR(+BJ20/(BF20*3.6)," ") -> 17.041667 | BH20: =IF(BI20>0,BI19," ") -> 1545015 | BI20: 1546242 | BJ20: =IFERROR((BI20-BH20)," ") -> 1227 | BK20: 70 | BL20: =IFERROR(+BO20/(BK20*3.6)," ") -> 11.734127 | BM20: =IF(BN20>0,BN19," ") -> 6165025 | BN20: 6167982 | BO20: =IFERROR((BN20-BM20)," ") -> 2957
A21: =MONTH(B21) -> 1 | B21: 46039 | C21: 38 | D21: =IFERROR(+G21/(C21*3.6)," ") -> 13.450292 | E21: =IF(F21>0,F20," ") -> 3765893 | F21: 3767733 | G21: =IFERROR((F21-E21)," ") -> 1840 | H21: 25 | I21: =IFERROR(+L21/(H21*3.6)," ") -> 0 | J21: =IF(K21>0,K20," ") -> 1970853 | K21: 1970853 | L21: =IFERROR((K21-J21)," ") -> 0 | M21: 38 | N21: =IFERROR(+Q21/(M21*3.6)," ") -> 0 | O21: =IF(P21>0,P20," ") -> 414656 | P21: 414656 | Q21: =IFERROR((P21-O21)," ") -> 0 | R21: =+BDFUENTES[[#This Row],[PZ MED m3/día]]/3.6/BDFUENTES[[#This Row],[PZ MED Horas Activo]] -> 28.347953 | S21: 19 | T21: =IF(U21>0,U20," ") -> 243549 | U21: 245488 | V21: =IFERROR((U21-T21)," ") -> 1939 | W21: =IFERROR((AA21/X21)/3.6," ") -> 323.27546 | X21: 24 | Y21: =IF(Z21>0,Z20," ") -> 1149600 | Z21: 1179470 | AA21: =IFERROR((Z21-Y21)," ")-1939 -> 27931 | AB21: =IFERROR(ROUNDDOWN(+AF21/(AC21*3.6),0)," ") -> 57 | AC21: 23 | AD21: =IF(AE21>0,AE20," ") -> 5152286 | AE21: 5157086 | AF21: =IFERROR((AE21-AD21)," ") -> 4800 | AG21: 20 | AH21: 24 | AK21: =IF(OR(AH21="",AG21=""),"",AH21*AG21*3.6) -> 1728 | AL21: =+BDFUENTES[[#This Row],[PZ CHB m3/día]]/3.6/BDFUENTES[[#This Row],[PZ CHB Horas Activo]] -> 37.947531 | AM21: 18 | AN21: =IF(AO21>0,AO20," ") -> 3548743 | AO21: 3551202 | AP21: =IFERROR((AO21-AN21)," ") -> 2459 | AR21: =IFERROR(+AU21/(AQ21*3.6)," ") | AS21: =IF(AT21>0,AT20," ") | AU21: =IFERROR((AT21-AS21)," ") | AV21: =+BDFUENTES[[#This Row],[PZ TM m3/día]]/3.6/BDFUENTES[[#This Row],[PZ TM Horas Activo]] -> 11.5 | AW21: 15 | AX21: =IF(AY21>0,AY20," ") -> 574295 | AY21: 574916 | AZ21: =IFERROR((AY21-AX21)," ") -> 621 | BA21: 125 | BB21: =IFERROR(+BE21/(BA21*3.6)," ") -> 4.0777778 | BC21: =IF(BD21>0,BD20," ") -> 5898670 | BD21: 5900505 | BE21: =IFERROR((BD21-BC21)," ") -> 1835 | BF21: 20 | BG21: =IFERROR(+BJ21/(BF21*3.6)," ") -> 16.791667 | BH21: =IF(BI21>0,BI20," ") -> 1546242 | BI21: 1547451 | BJ21: =IFERROR((BI21-BH21)," ") -> 1209 | BK21: 70 | BL21: =IFERROR(+BO21/(BK21*3.6)," ") -> 16.65873 | BM21: =IF(BN21>0,BN20," ") -> 6167982 | BN21: 6172180 | BO21: =IFERROR((BN21-BM21)," ") -> 4198
A22: =MONTH(B22) -> 1 | B22: 46040 | C22: 38 | D22: =IFERROR(+G22/(C22*3.6)," ") -> 13.230994 | E22: =IF(F22>0,F21," ") -> 3767733 | F22: 3769543 | G22: =IFERROR((F22-E22)," ") -> 1810 | H22: 25 | I22: =IFERROR(+L22/(H22*3.6)," ") -> 0 | J22: =IF(K22>0,K21," ") -> 1970853 | K22: 1970853 | L22: =IFERROR((K22-J22)," ") -> 0 | M22: 38 | N22: =IFERROR(+Q22/(M22*3.6)," ") -> 0 | O22: =IF(P22>0,P21," ") -> 414656 | P22: 414656 | Q22: =IFERROR((P22-O22)," ") -> 0 | R22: =+BDFUENTES[[#This Row],[PZ MED m3/día]]/3.6/BDFUENTES[[#This Row],[PZ MED Horas Activo]] -> 27.777778 | S22: 0.01 | T22: =IF(U22>0,U21," ") -> 245488 | U22: 245489 | V22: =IFERROR((U22-T22)," ") -> 1 | W22: =IFERROR((AA22/X22)/3.6," ") -> 372.53878 | X22: 24 | Y22: =IF(Z22>0,Z21," ") -> 1179470 | Z22: 1211657.4 | AA22: =IFERROR((Z22-Y22)," ") -> 32187.35 | AB22: =IFERROR(ROUNDDOWN(+AF22/(AC22*3.6),0)," ") -> 60 | AC22: 19 | AD22: =IF(AE22>0,AE21," ") -> 5157086 | AE22: 5161200 | AF22: =IFERROR((AE22-AD22)," ") -> 4114 | AG22: 20 | AH22: 24 | AK22: =IF(OR(AH22="",AG22=""),"",AH22*AG22*3.6) -> 1728 | AL22: =+BDFUENTES[[#This Row],[PZ CHB m3/día]]/3.6/BDFUENTES[[#This Row],[PZ CHB Horas Activo]] -> 38.564815 | AM22: 18 | AN22: =IF(AO22>0,AO21," ") -> 3551202 | AO22: 3553701 | AP22: =IFERROR((AO22-AN22)," ") -> 2499 | AR22: =IFERROR(+AU22/(AQ22*3.6)," ") | AS22: =IF(AT22>0,AT21," ") | AU22: =IFERROR((AT22-AS22)," ") | AV22: =+BDFUENTES[[#This Row],[PZ TM m3/día]]/3.6/BDFUENTES[[#This Row],[PZ TM Horas Activo]] -> 11.148148 | AW22: 15 | AX22: =IF(AY22>0,AY21," ") -> 574916 | AY22: 575518 | AZ22: =IFERROR((AY22-AX22)," ") -> 602 | BA22: 125 | BB22: =IFERROR(+BE22/(BA22*3.6)," ") -> 4.1377778 | BC22: =IF(BD22>0,BD21," ") -> 5900505 | BD22: 5902367 | BE22: =IFERROR((BD22-BC22)," ") -> 1862 | BF22: 20 | BG22: =IFERROR(+BJ22/(BF22*3.6)," ") -> 16.208333 | BH22: =IF(BI22>0,BI21," ") -> 1547451 | BI22: 1548618 | BJ22: =IFERROR((BI22-BH22)," ") -> 1167 | BK22: 70 | BL22: =IFERROR(+BO22/(BK22*3.6)," ") -> 14.507937 | BM22: =IF(BN22>0,BN21," ") -> 6172180 | BN22: 6175836 | BO22: =IFERROR((BN22-BM22)," ") -> 3656
A23: =MONTH(B23) -> 1 | B23: 46041 | C23: 38 | D23: =IFERROR(+G23/(C23*3.6)," ") -> 13.377193 | E23: =IF(F23>0,F22," ") -> 3769543 | F23: 3771373 | G23: =IFERROR((F23-E23)," ") -> 1830 | H23: 25 | I23: =IFERROR(+L23/(H23*3.6)," ") -> 0 | J23: =IF(K23>0,K22," ") -> 1970853 | K23: 1970853 | L23: =IFERROR((K23-J23)," ") -> 0 | M23: 38 | N23: =IFERROR(+Q23/(M23*3.6)," ") -> 0 | O23: =IF(P23>0,P22," ") -> 414656 | P23: 414656 | Q23: =IFERROR((P23-O23)," ") -> 0 | R23: =+BDFUENTES[[#This Row],[PZ MED m3/día]]/3.6/BDFUENTES[[#This Row],[PZ MED Horas Activo]] -> 27.700617 | S23: 18 | T23: =IF(U23>0,U22," ") -> 245489 | U23: 247284 | V23: =IFERROR((U23-T23)," ") -> 1795 | W23: =IFERROR((AA23/X23)/3.6," ") -> 265.97974 | X23: 24 | Y23: =IF(Z23>0,Z22," ") -> 1211657.4 | Z23: 1236433 | AA23: =IFERROR((Z23-Y23)," ")-1795 -> 22980.65 | AB23: =IFERROR(ROUNDDOWN(+AF23/(AC23*3.6),0)," ") -> 58 | AC23: 15 | AD23: =IF(AE23>0,AE22," ") -> 5161200 | AE23: 5164362 | AF23: =IFERROR((AE23-AD23)," ") -> 3162 | AG23: 20 | AH23: 24 | AK23: =IF(OR(AH23="",AG23=""),"",AH23*AG23*3.6) -> 1728 | AL23: =+BDFUENTES[[#This Row],[PZ CHB m3/día]]/3.6/BDFUENTES[[#This Row],[PZ CHB Horas Activo]] -> 38.302469 | AM23: 18 | AN23: =IF(AO23>0,AO22," ") -> 3553701 | AO23: 3556183 | AP23: =IFERROR((AO23-AN23)," ") -> 2482 | AR23: =IFERROR(+AU23/(AQ23*3.6)," ") | AS23: =IF(AT23>0,AT22," ") | AU23: =IFERROR((AT23-AS23)," ") | AV23: =+BDFUENTES[[#This Row],[PZ TM m3/día]]/3.6/BDFUENTES[[#This Row],[PZ TM Horas Activo]] -> 11.289683 | AW23: 14 | AX23: =IF(AY23>0,AY22," ") -> 575518 | AY23: 576087 | AZ23: =IFERROR((AY23-AX23)," ") -> 569 | BA23: 125 | BB23: =IFERROR(+BE23/(BA23*3.6)," ") -> 4.1688889 | BC23: =IF(BD23>0,BD22," ") -> 5902367 | BD23: 5904243 | BE23: =IFERROR((BD23-BC23)," ") -> 1876 | BF23: 20 | BG23: =IFERROR(+BJ23/(BF23*3.6)," ") -> 16.222222 | BH23: =IF(BI23>0,BI22," ") -> 1548618 | BI23: 1549786 | BJ23: =IFERROR((BI23-BH23)," ") -> 1168 | BK23: 70 | BL23: =IFERROR(+BO23/(BK23*3.6)," ") -> 5.0515873 | BM23: =IF(BN23>0,BN22," ") -> 6175836 | BN23: 6177109 | BO23: =IFERROR((BN23-BM23)," ") -> 1273
A24: =MONTH(B24) -> 1 | B24: 46042 | C24: 38 | D24: =IFERROR(+G24/(C24*3.6)," ") -> 13.464912 | E24: =IF(F24>0,F23," ") -> 3771373 | F24: 3773215 | G24: =IFERROR((F24-E24)," ") -> 1842 | H24: 25 | I24: =IFERROR(+L24/(H24*3.6)," ") -> 0 | J24: =IF(K24>0,K23," ") -> 1970853 | K24: 1970853 | L24: =IFERROR((K24-J24)," ") -> 0 | M24: 38 | N24: =IFERROR(+Q24/(M24*3.6)," ") -> 0 | O24: =IF(P24>0,P23," ") -> 414656 | P24: 414656 | Q24: =IFERROR((P24-O24)," ") -> 0 | R24: =+BDFUENTES[[#This Row],[PZ MED m3/día]]/3.6/BDFUENTES[[#This Row],[PZ MED Horas Activo]] -> 28.494152 | S24: 19 | T24: =IF(U24>0,U23," ") -> 247284 | U24: 249233 | V24: =IFERROR((U24-T24)," ") -> 1949 | W24: =IFERROR((AA24/X24)/3.6," ") -> 339.37074 | X24: 24 | Y24: =IF(Z24>0,Z23," ") -> 1236433 | Z24: 1267703.6 | AA24: =IFERROR((Z24-Y24)," ")-1949 -> 29321.632 | AB24: =IFERROR(ROUNDDOWN(+AF24/(AC24*3.6),0)," ") -> 52 | AC24: 23.3 | AD24: =IF(AE24>0,AE23," ") -> 5164362 | AE24: 5168753 | AF24: =IFERROR((AE24-AD24)," ") -> 4391 | AG24: 20 | AH24: 24 | AK24: =IF(OR(AH24="",AG24=""),"",AH24*AG24*3.6) -> 1728 | AL24: =+BDFUENTES[[#This Row],[PZ CHB m3/día]]/3.6/BDFUENTES[[#This Row],[PZ CHB Horas Activo]] -> 38.796296 | AM24: 18 | AN24: =IF(AO24>0,AO23," ") -> 3556183 | AO24: 3558697 | AP24: =IFERROR((AO24-AN24)," ") -> 2514 | AR24: =IFERROR(+AU24/(AQ24*3.6)," ") | AS24: =IF(AT24>0,AT23," ") | AU24: =IFERROR((AT24-AS24)," ") | AV24: =+BDFUENTES[[#This Row],[PZ TM m3/día]]/3.6/BDFUENTES[[#This Row],[PZ TM Horas Activo]] -> 11.777778 | AW24: 15 | AX24: =IF(AY24>0,AY23," ") -> 576087 | AY24: 576723 | AZ24: =IFERROR((AY24-AX24)," ") -> 636 | BA24: 125 | BB24: =IFERROR(+BE24/(BA24*3.6)," ") -> 4.0888889 | BC24: =IF(BD24>0,BD23," ") -> 5904243 | BD24: 5906083 | BE24: =IFERROR((BD24-BC24)," ") -> 1840 | BF24: 20 | BG24: =IFERROR(+BJ24/(BF24*3.6)," ") -> 8.3472222 | BH24: =IF(BI24>0,BI23," ") -> 1549786 | BI24: 1550387 | BJ24: =IFERROR((BI24-BH24)," ") -> 601 | BK24: 70 | BL24: =IFERROR(+BO24/(BK24*3.6)," ") -> 17.123016 | BM24: =IF(BN24>0,BN23," ") -> 6177109 | BN24: 6181424 | BO24: =IFERROR((BN24-BM24)," ") -> 4315
A25: =MONTH(B25) -> 1 | B25: 46043 | C25: 38 | D25: =IFERROR(+G25/(C25*3.6)," ") -> 13.267544 | E25: =IF(F25>0,F24," ") -> 3773215 | F25: 3775030 | G25: =IFERROR((F25-E25)," ") -> 1815 | H25: 25 | I25: =IFERROR(+L25/(H25*3.6)," ") -> 0 | J25: =IF(K25>0,K24," ") -> 1970853 | K25: 1970853 | L25: =IFERROR((K25-J25)," ") -> 0 | M25: 38 | N25: =IFERROR(+Q25/(M25*3.6)," ") -> 0 | O25: =IF(P25>0,P24," ") -> 414656 | P25: 414656 | Q25: =IFERROR((P25-O25)," ") -> 0 | R25: =+BDFUENTES[[#This Row],[PZ MED m3/día]]/3.6/BDFUENTES[[#This Row],[PZ MED Horas Activo]] -> 28.777778 | S25: 20 | T25: =IF(U25>0,U24," ") -> 249233 | U25: 251305 | V25: =IFERROR((U25-T25)," ") -> 2072 | W25: =IFERROR((AA25/X25)/3.6," ") -> 389.44394 | X25: 24 | Y25: =IF(Z25>0,Z24," ") -> 1267703.6 | Z25: 1303300.6 | AA25: =IFERROR((Z25-Y25)," ")-1949 -> 33647.957 | AB25: =IFERROR(ROUNDDOWN(+AF25/(AC25*3.6),0)," ") -> 69 | AC25: 13 | AD25: =IF(AE25>0,AE24," ") -> 5168753 | AE25: 5171997 | AF25: =IFERROR((AE25-AD25)," ") -> 3244 | AG25: 20 | AH25: 24 | AK25: =IF(OR(AH25="",AG25=""),"",AH25*AG25*3.6) -> 1728 | AL25: =+BDFUENTES[[#This Row],[PZ CHB m3/día]]/3.6/BDFUENTES[[#This Row],[PZ CHB Horas Activo]] -> 38.348765 | AM25: 18 | AN25: =IF(AO25>0,AO24," ") -> 3558697 | AO25: 3561182 | AP25: =IFERROR((AO25-AN25)," ") -> 2485 | AR25: =IFERROR(+AU25/(AQ25*3.6)," ") | AS25: =IF(AT25>0,AT24," ") | AU25: =IFERROR((AT25-AS25)," ") | AV25: =+BDFUENTES[[#This Row],[PZ TM m3/día]]/3.6/BDFUENTES[[#This Row],[PZ TM Horas Activo]] -> 11.444444 | AW25: 15 | AX25: =IF(AY25>0,AY24," ") -> 576723 | AY25: 577341 | AZ25: =IFERROR((AY25-AX25)," ") -> 618 | BA25: 125 | BB25: =IFERROR(+BE25/(BA25*3.6)," ") -> 4.1866667 | BC25: =IF(BD25>0,BD24," ") -> 5906083 | BD25: 5907967 | BE25: =IFERROR((BD25-BC25)," ") -> 1884 | BF25: 20 | BG25: =IFERROR(+BJ25/(BF25*3.6)," ") -> 13.569444 | BH25: =IF(BI25>0,BI24," ") -> 1550387 | BI25: 1551364 | BJ25: =IFERROR((BI25-BH25)," ") -> 977 | BK25: 70 | BL25: =IFERROR(+BO25/(BK25*3.6)," ") -> 18.833333 | BM25: =IF(BN25>0,BN24," ") -> 6181424 | BN25: 6186170 | BO25: =IFERROR((BN25-BM25)," ") -> 4746
A26: =MONTH(B26) -> 1 | B26: 46044 | C26: 38 | D26: =IFERROR(+G26/(C26*3.6)," ") -> 13.296784 | E26: =IF(F26>0,F25," ") -> 3775030 | F26: 3776849 | G26: =IFERROR((F26-E26)," ") -> 1819 | H26: 25 | I26: =IFERROR(+L26/(H26*3.6)," ") -> 0 | J26: =IF(K26>0,K25," ") -> 1970853 | K26: 1970853 | L26: =IFERROR((K26-J26)," ") -> 0 | M26: 38 | N26: =IFERROR(+Q26/(M26*3.6)," ") -> 0 | O26: =IF(P26>0,P25," ") -> 414656 | P26: 414656 | Q26: =IFERROR((P26-O26)," ") -> 0 | R26: =+BDFUENTES[[#This Row],[PZ MED m3/día]]/3.6/BDFUENTES[[#This Row],[PZ MED Horas Activo]] -> 28.533951 | S26: 18 | T26: =IF(U26>0,U25," ") -> 251305 | U26: 253154 | V26: =IFERROR((U26-T26)," ") -> 1849 | W26: =IFERROR((AA26/X26)/3.6," ") -> 372.7131 | X26: 24 | Y26: =IF(Z26>0,Z25," ") -> 1303300.6 | Z26: 1337352 | AA26: =IFERROR((Z26-Y26)," ")-1849 -> 32202.412 | AB26: =IFERROR(ROUNDDOWN(+AF26/(AC26*3.6),0)," ") -> 63 | AC26: 24 | AD26: =IF(AE26>0,AE25," ") -> 5171997 | AE26: 5177487 | AF26: =IFERROR((AE26-AD26)," ") -> 5490 | AG26: 20 | AH26: 24 | AK26: =IF(OR(AH26="",AG26=""),"",AH26*AG26*3.6) -> 1728 | AL26: =+BDFUENTES[[#This Row],[PZ CHB m3/día]]/3.6/BDFUENTES[[#This Row],[PZ CHB Horas Activo]] -> 38.830409 | AM26: 19 | AN26: =IF(AO26>0,AO25," ") -> 3561182 | AO26: 3563838 | AP26: =IFERROR((AO26-AN26)," ") -> 2656 | AR26: =IFERROR(+AU26/(AQ26*3.6)," ") | AS26: =IF(AT26>0,AT25," ") | AU26: =IFERROR((AT26-AS26)," ") | AV26: =+BDFUENTES[[#This Row],[PZ TM m3/día]]/3.6/BDFUENTES[[#This Row],[PZ TM Horas Activo]] -> 11.685185 | AW26: 15 | AX26: =IF(AY26>0,AY25," ") -> 577341 | AY26: 577972 | AZ26: =IFERROR((AY26-AX26)," ") -> 631 | BA26: 125 | BB26: =IFERROR(+BE26/(BA26*3.6)," ") -> 4.16 | BC26: =IF(BD26>0,BD25," ") -> 5907967 | BD26: 5909839 | BE26: =IFERROR((BD26-BC26)," ") -> 1872 | BF26: 20 | BG26: =IFERROR(+BJ26/(BF26*3.6)," ") -> 17.333333 | BH26: =IF(BI26>0,BI25," ") -> 1551364 | BI26: 1552612 | BJ26: =IFERROR((BI26-BH26)," ") -> 1248 | BK26: 70 | BL26: =IFERROR(+BO26/(BK26*3.6)," ") -> 16.690476 | BM26: =IF(BN26>0,BN25," ") -> 6186170 | BN26: 6190376 | BO26: =IFERROR((BN26-BM26)," ") -> 4206
A27: =MONTH(B27) -> 1 | B27: 46045 | C27: 38 | D27: =IFERROR(+G27/(C27*3.6)," ") -> 13.282164 | E27: =IF(F27>0,F26," ") -> 3776849 | F27: 3778666 | G27: =IFERROR((F27-E27)," ") -> 1817 | H27: 25 | I27: =IFERROR(+L27/(H27*3.6)," ") -> 0 | J27: =IF(K27>0,K26," ") -> 1970853 | K27: 1970853 | L27: =IFERROR((K27-J27)," ") -> 0 | M27: 38 | N27: =IFERROR(+Q27/(M27*3.6)," ") -> 0 | O27: =IF(P27>0,P26," ") -> 414656 | P27: 414656 | Q27: =IFERROR((P27-O27)," ") -> 0 | R27: =+BDFUENTES[[#This Row],[PZ MED m3/día]]/3.6/BDFUENTES[[#This Row],[PZ MED Horas Activo]] -> 28.024691 | S27: 18 | T27: =IF(U27>0,U26," ") -> 253154 | U27: 254970 | V27: =IFERROR((U27-T27)," ") -> 1816 | W27: =IFERROR((AA27/X27)/3.6," ") -> 367.15863 | X27: 24 | Y27: =IF(Z27>0,Z26," ") -> 1337352 | Z27: 1370890.5 | AA27: =IFERROR((Z27-Y27)," ")-1816 -> 31722.506 | AB27: =IFERROR(ROUNDDOWN(+AF27/(AC27*3.6),0)," ") -> 67 | AC27: 24 | AD27: =IF(AE27>0,AE26," ") -> 5177487 | AE27: 5183284 | AF27: =IFERROR((AE27-AD27)," ") -> 5797 | AG27: 20 | AH27: 24 | AK27: =IF(OR(AH27="",AG27=""),"",AH27*AG27*3.6) -> 1728 | AL27: =+BDFUENTES[[#This Row],[PZ CHB m3/día]]/3.6/BDFUENTES[[#This Row],[PZ CHB Horas Activo]] -> 38.009259 | AM27: 18 | AN27: =IF(AO27>0,AO26," ") -> 3563838 | AO27: 3566301 | AP27: =IFERROR((AO27-AN27)," ") -> 2463 | AR27: =IFERROR(+AU27/(AQ27*3.6)," ") | AS27: =IF(AT27>0,AT26," ") | AU27: =IFERROR((AT27-AS27)," ") | AV27: =+BDFUENTES[[#This Row],[PZ TM m3/día]]/3.6/BDFUENTES[[#This Row],[PZ TM Horas Activo]] -> 11.574074 | AW27: 15 | AX27: =IF(AY27>0,AY26," ") -> 577972 | AY27: 578597 | AZ27: =IFERROR((AY27-AX27)," ") -> 625 | BA27: 125 | BB27: =IFERROR(+BE27/(BA27*3.6)," ") -> 4.2355556 | BC27: =IF(BD27>0,BD26," ") -> 5909839 | BD27: 5911745 | BE27: =IFERROR((BD27-BC27)," ") -> 1906 | BF27: 20 | BG27: =IFERROR(+BJ27/(BF27*3.6)," ") -> 4.3472222 | BH27: =IF(BI27>0,BI26," ") -> 1552612 | BI27: 1552925 | BJ27: =IFERROR((BI27-BH27)," ") -> 313 | BK27: 70 | BL27: =IFERROR(+BO27/(BK27*3.6)," ") -> 16.019841 | BM27: =IF(BN27>0,BN26," ") -> 6190376 | BN27: 6194413 | BO27: =IFERROR((BN27-BM27)," ") -> 4037
A28: =MONTH(B28) -> 1 | B28: 46046 | C28: 38 | D28: =IFERROR(+G28/(C28*3.6)," ") -> 13.428363 | E28: =IF(F28>0,F27," ") -> 3778666 | F28: 3780503 | G28: =IFERROR((F28-E28)," ") -> 1837 | H28: 25 | I28: =IFERROR(+L28/(H28*3.6)," ") -> 0 | J28: =IF(K28>0,K27," ") -> 1970853 | K28: 1970853 | L28: =IFERROR((K28-J28)," ") -> 0 | M28: 38 | N28: =IFERROR(+Q28/(M28*3.6)," ") -> 0 | O28: =IF(P28>0,P27," ") -> 414656 | P28: 414656 | Q28: =IFERROR((P28-O28)," ") -> 0 | R28: =+BDFUENTES[[#This Row],[PZ MED m3/día]]/3.6/BDFUENTES[[#This Row],[PZ MED Horas Activo]] -> 29.548611 | S28: 24 | T28: =IF(U28>0,U27," ") -> 254970 | U28: 257523 | V28: =IFERROR((U28-T28)," ") -> 2553 | W28: =IFERROR((AA28/X28)/3.6," ") -> 370.32631 | X28: 24 | Y28: =IF(Z28>0,Z27," ") -> 1370890.5 | Z28: 1405439.7 | AA28: =IFERROR((Z28-Y28)," ")-2553 -> 31996.193 | AB28: =IFERROR(ROUNDDOWN(+AF28/(AC28*3.6),0)," ") -> 69 | AC28: 24 | AD28: =IF(AE28>0,AE27," ") -> 5183284 | AE28: 5189330 | AF28: =IFERROR((AE28-AD28)," ") -> 6046 | AG28: 20 | AH28: 24 | AK28: =IF(OR(AH28="",AG28=""),"",AH28*AG28*3.6) -> 1728 | AL28: =+BDFUENTES[[#This Row],[PZ CHB m3/día]]/3.6/BDFUENTES[[#This Row],[PZ CHB Horas Activo]] -> 39.058642 | AM28: 18 | AN28: =IF(AO28>0,AO27," ") -> 3566301 | AO28: 3568832 | AP28: =IFERROR((AO28-AN28)," ") -> 2531 | AR28: =IFERROR(+AU28/(AQ28*3.6)," ") | AS28: =IF(AT28>0,AT27," ") | AU28: =IFERROR((AT28-AS28)," ") | AV28: =+BDFUENTES[[#This Row],[PZ TM m3/día]]/3.6/BDFUENTES[[#This Row],[PZ TM Horas Activo]] -> 11.351852 | AW28: 15 | AX28: =IF(AY28>0,AY27," ") -> 578597 | AY28: 579210 | AZ28: =IFERROR((AY28-AX28)," ") -> 613 | BA28: 125 | BB28: =IFERROR(+BE28/(BA28*3.6)," ") -> 4.1822222 | BC28: =IF(BD28>0,BD27," ") -> 5911745 | BD28: 5913627 | BE28: =IFERROR((BD28-BC28)," ") -> 1882 | BF28: 20 | BG28: =IFERROR(+BJ28/(BF28*3.6)," ") -> 18.527778 | BH28: =IF(BI28>0,BI27," ") -> 1552925 | BI28: 1554259 | BJ28: =IFERROR((BI28-BH28)," ") -> 1334 | BK28: 70 | BL28: =IFERROR(+BO28/(BK28*3.6)," ") -> 10.329365 | BM28: =IF(BN28>0,BN27," ") -> 6194413 | BN28: 6197016 | BO28: =IFERROR((BN28-BM28)," ") -> 2603
A29: =MONTH(B29) -> 1 | B29: 46047 | C29: 38 | D29: =IFERROR(+G29/(C29*3.6)," ") -> 13.318713 | E29: =IF(F29>0,F28," ") -> 3780503 | F29: 3782325 | G29: =IFERROR((F29-E29)," ") -> 1822 | H29: 25 | I29: =IFERROR(+L29/(H29*3.6)," ") -> 0 | J29: =IF(K29>0,K28," ") -> 1970853 | K29: 1970853 | L29: =IFERROR((K29-J29)," ") -> 0 | M29: 38 | N29: =IFERROR(+Q29/(M29*3.6)," ") -> 0 | O29: =IF(P29>0,P28," ") -> 414656 | P29: 414656 | Q29: =IFERROR((P29-O29)," ") -> 0 | R29: =+BDFUENTES[[#This Row],[PZ MED m3/día]]/3.6/BDFUENTES[[#This Row],[PZ MED Horas Activo]] -> 28.18287 | S29: 24 | T29: =IF(U29>0,U28," ") -> 257523 | U29: 259958 | V29: =IFERROR((U29-T29)," ") -> 2435 | W29: =IFERROR((AA29/X29)/3.6," ") -> 342.43404 | X29: 24 | Y29: =IF(Z29>0,Z28," ") -> 1405439.7 | Z29: 1437461 | AA29: =IFERROR((Z29-Y29)," ")-2435 -> 29586.301 | AB29: =IFERROR(ROUNDDOWN(+AF29/(AC29*3.6),0)," ") -> 77 | AC29: 24 | AD29: =IF(AE29>0,AE28," ") -> 5189330 | AE29: 5195998 | AF29: =IFERROR((AE29-AD29)," ") -> 6668 | AG29: 20 | AH29: 24 | AK29: =IF(OR(AH29="",AG29=""),"",AH29*AG29*3.6) -> 1728 | AL29: =+BDFUENTES[[#This Row],[PZ CHB m3/día]]/3.6/BDFUENTES[[#This Row],[PZ CHB Horas Activo]] -> 37.947531 | AM29: 18 | AN29: =IF(AO29>0,AO28," ") -> 3568832 | AO29: 3571291 | AP29: =IFERROR((AO29-AN29)," ") -> 2459 | AR29: =IFERROR(+AU29/(AQ29*3.6)," ") | AS29: =IF(AT29>0,AT28," ") | AU29: =IFERROR((AT29-AS29)," ") | AV29: =+BDFUENTES[[#This Row],[PZ TM m3/día]]/3.6/BDFUENTES[[#This Row],[PZ TM Horas Activo]] -> 11.166667 | AW29: 15 | AX29: =IF(AY29>0,AY28," ") -> 579210 | AY29: 579813 | AZ29: =IFERROR((AY29-AX29)," ") -> 603 | BA29: 125 | BB29: =IFERROR(+BE29/(BA29*3.6)," ") -> 4.0244444 | BC29: =IF(BD29>0,BD28," ") -> 5913627 | BD29: 5915438 | BE29: =IFERROR((BD29-BC29)," ") -> 1811 | BF29: 20 | BG29: =IFERROR(+BJ29/(BF29*3.6)," ") -> 16.486111 | BH29: =IF(BI29>0,BI28," ") -> 1554259 | BI29: 1555446 | BJ29: =IFERROR((BI29-BH29)," ") -> 1187 | BK29: 70 | BL29: =IFERROR(+BO29/(BK29*3.6)," ") -> 18.543651 | BM29: =IF(BN29>0,BN28," ") -> 6197016 | BN29: 6201689 | BO29: =IFERROR((BN29-BM29)," ") -> 4673
A30: =MONTH(B30) -> 1 | B30: 46048 | C30: 38 | D30: =IFERROR(+G30/(C30*3.6)," ") -> 12.872807 | E30: =IF(F30>0,F29," ") -> 3782325 | F30: 3784086 | G30: =IFERROR((F30-E30)," ") -> 1761 | H30: 25 | I30: =IFERROR(+L30/(H30*3.6)," ") -> 0 | J30: =IF(K30>0,K29," ") -> 1970853 | K30: 1970853 | L30: =IFERROR((K30-J30)," ") -> 0 | M30: 38 | N30: =IFERROR(+Q30/(M30*3.6)," ") -> 0 | O30: =IF(P30>0,P29," ") -> 414656 | P30: 414656 | Q30: =IFERROR((P30-O30)," ") -> 0 | R30: =+BDFUENTES[[#This Row],[PZ MED m3/día]]/3.6/BDFUENTES[[#This Row],[PZ MED Horas Activo]] -> 28.179012 | S30: 18 | T30: =IF(U30>0,U29," ") -> 259958 | U30: 261784 | V30: =IFERROR((U30-T30)," ") -> 1826 | W30: =IFERROR((AA30/X30)/3.6," ") -> 354.83057 | X30: 24 | Y30: =IF(Z30>0,Z29," ") -> 1437461 | Z30: 1469944.4 | AA30: =IFERROR((Z30-Y30)," ")-1826 -> 30657.361 | AB30: =IFERROR(ROUNDDOWN(+AF30/(AC30*3.6),0)," ") -> 69 | AC30: 24 | AD30: =IF(AE30>0,AE29," ") -> 5195998 | AE30: 5202017 | AF30: =IFERROR((AE30-AD30)," ") -> 6019 | AG30: 20 | AH30: 24 | AK30: =IF(OR(AH30="",AG30=""),"",AH30*AG30*3.6) -> 1728 | AL30: =+BDFUENTES[[#This Row],[PZ CHB m3/día]]/3.6/BDFUENTES[[#This Row],[PZ CHB Horas Activo]] -> 38.472222 | AM30: 18 | AN30: =IF(AO30>0,AO29," ") -> 3571291 | AO30: 3573784 | AP30: =IFERROR((AO30-AN30)," ") -> 2493 | AR30: =IFERROR(+AU30/(AQ30*3.6)," ") | AS30: =IF(AT30>0,AT29," ") | AU30: =IFERROR((AT30-AS30)," ") | AV30: =+BDFUENTES[[#This Row],[PZ TM m3/día]]/3.6/BDFUENTES[[#This Row],[PZ TM Horas Activo]] -> 11.72619 | AW30: 14 | AX30: =IF(AY30>0,AY29," ") -> 579813 | AY30: 580404 | AZ30: =IFERROR((AY30-AX30)," ") -> 591 | BA30: 125 | BB30: =IFERROR(+BE30/(BA30*3.6)," ") -> 4.1044444 | BC30: =IF(BD30>0,BD29," ") -> 5915438 | BD30: 5917285 | BE30: =IFERROR((BD30-BC30)," ") -> 1847 | BF30: 20 | BG30: =IFERROR(+BJ30/(BF30*3.6)," ") -> 8.4027778 | BH30: =IF(BI30>0,BI29," ") -> 1555446 | BI30: 1556051 | BJ30: =IFERROR((BI30-BH30)," ") -> 605 | BK30: 70 | BL30: =IFERROR(+BO30/(BK30*3.6)," ") -> 14.738095 | BM30: =IF(BN30>0,BN29," ") -> 6201689 | BN30: 6205403 | BO30: =IFERROR((BN30-BM30)," ") -> 3714
A31: =MONTH(B31) -> 1 | B31: 46049 | C31: 38 | D31: =IFERROR(+G31/(C31*3.6)," ") -> 13.589181 | E31: =IF(F31>0,F30," ") -> 3784086 | F31: 3785945 | G31: =IFERROR((F31-E31)," ") -> 1859 | H31: 25 | I31: =IFERROR(+L31/(H31*3.6)," ") -> 0 | J31: =IF(K31>0,K30," ") -> 1970853 | K31: 1970853 | L31: =IFERROR((K31-J31)," ") -> 0 | M31: 38 | N31: =IFERROR(+Q31/(M31*3.6)," ") -> 0 | O31: =IF(P31>0,P30," ") -> 414656 | P31: 414656 | Q31: =IFERROR((P31-O31)," ") -> 0 | R31: =+BDFUENTES[[#This Row],[PZ MED m3/día]]/3.6/BDFUENTES[[#This Row],[PZ MED Horas Activo]] -> 29.152778 | S31: 20 | T31: =IF(U31>0,U30," ") -> 261784 | U31: 263883 | V31: =IFERROR((U31-T31)," ") -> 2099 | W31: =IFERROR((AA31/X31)/3.6," ") -> 342.56479 | X31: 24 | Y31: =IF(Z31>0,Z30," ") -> 1469944.4 | Z31: 1501641 | AA31: =IFERROR((Z31-Y31)," ")-2099 -> 29597.598 | AB31: =IFERROR(ROUNDDOWN(+AF31/(AC31*3.6),0)," ") -> 73 | AC31: 24 | AD31: =IF(AE31>0,AE30," ") -> 5202017 | AE31: 5208378 | AF31: =IFERROR((AE31-AD31)," ") -> 6361 | AG31: 20 | AH31: 24 | AK31: =IF(OR(AH31="",AG31=""),"",AH31*AG31*3.6) -> 1728 | AL31: =+BDFUENTES[[#This Row],[PZ CHB m3/día]]/3.6/BDFUENTES[[#This Row],[PZ CHB Horas Activo]] -> 38.132716 | AM31: 18 | AN31: =IF(AO31>0,AO30," ") -> 3573784 | AO31: 3576255 | AP31: =IFERROR((AO31-AN31)," ") -> 2471 | AR31: =IFERROR(+AU31/(AQ31*3.6)," ") | AS31: =IF(AT31>0,AT30," ") | AU31: =IFERROR((AT31-AS31)," ") | AV31: =+BDFUENTES[[#This Row],[PZ TM m3/día]]/3.6/BDFUENTES[[#This Row],[PZ TM Horas Activo]] -> 11.351852 | AW31: 15 | AX31: =IF(AY31>0,AY30," ") -> 580404 | AY31: 581017 | AZ31: =IFERROR((AY31-AX31)," ") -> 613 | BA31: 125 | BB31: =IFERROR(+BE31/(BA31*3.6)," ") -> 4.14 | BC31: =IF(BD31>0,BD30," ") -> 5917285 | BD31: 5919148 | BE31: =IFERROR((BD31-BC31)," ") -> 1863 | BF31: 20 | BG31: =IFERROR(+BJ31/(BF31*3.6)," ") -> 16.888889 | BH31: =IF(BI31>0,BI30," ") -> 1556051 | BI31: 1557267 | BJ31: =IFERROR((BI31-BH31)," ") -> 1216 | BK31: 70 | BL31: =IFERROR(+BO31/(BK31*3.6)," ") -> 18.166667 | BM31: =IF(BN31>0,BN30," ") -> 6205403 | BN31: 6209981 | BO31: =IFERROR((BN31-BM31)," ") -> 4578
A32: =MONTH(B32) -> 1 | B32: 46050 | C32: 38 | D32: =IFERROR(+G32/(C32*3.6)," ") -> 13.055556 | E32: =IF(F32>0,F31," ") -> 3785945 | F32: 3787731 | G32: =IFERROR((F32-E32)," ") -> 1786 | H32: 25 | I32: =IFERROR(+L32/(H32*3.6)," ") -> 0 | J32: =IF(K32>0,K31," ") -> 1970853 | K32: 1970853 | L32: =IFERROR((K32-J32)," ") -> 0 | M32: 38 | N32: =IFERROR(+Q32/(M32*3.6)," ") -> 0 | O32: =IF(P32>0,P31," ") -> 414656 | P32: 414656 | Q32: =IFERROR((P32-O32)," ") -> 0 | R32: =+BDFUENTES[[#This Row],[PZ MED m3/día]]/3.6/BDFUENTES[[#This Row],[PZ MED Horas Activo]] -> 28.121693 | S32: 21 | T32: =IF(U32>0,U31," ") -> 263883 | U32: 266009 | V32: =IFERROR((U32-T32)," ") -> 2126 | W32: =IFERROR((AA32/X32)/3.6," ") -> 325.28794 | X32: 24 | Y32: =IF(Z32>0,Z31," ") -> 1501641 | Z32: 1531871.8 | AA32: =IFERROR((Z32-Y32)," ")-2126 -> 28104.878 | AB32: =IFERROR(ROUNDDOWN(+AF32/(AC32*3.6),0)," ") -> 71 | AC32: 24 | AD32: =IF(AE32>0,AE31," ") -> 5208378 | AE32: 5214545 | AF32: =IFERROR((AE32-AD32)," ") -> 6167 | AG32: 20 | AH32: 24 | AK32: =IF(OR(AH32="",AG32=""),"",AH32*AG32*3.6) -> 1728 | AL32: =+BDFUENTES[[#This Row],[PZ CHB m3/día]]/3.6/BDFUENTES[[#This Row],[PZ CHB Horas Activo]] -> 39.351852 | AM32: 18 | AN32: =IF(AO32>0,AO31," ") -> 3576255 | AO32: 3578805 | AP32: =IFERROR((AO32-AN32)," ") -> 2550 | AR32: =IFERROR(+AU32/(AQ32*3.6)," ") | AS32: =IF(AT32>0,AT31," ") | AU32: =IFERROR((AT32-AS32)," ") | AV32: =+BDFUENTES[[#This Row],[PZ TM m3/día]]/3.6/BDFUENTES[[#This Row],[PZ TM Horas Activo]] -> 11.203704 | AW32: 15 | AX32: =IF(AY32>0,AY31," ") -> 581017 | AY32: 581622 | AZ32: =IFERROR((AY32-AX32)," ") -> 605 | BA32: 125 | BB32: =IFERROR(+BE32/(BA32*3.6)," ") -> 4.1288889 | BC32: =IF(BD32>0,BD31," ") -> 5919148 | BD32: 5921006 | BE32: =IFERROR((BD32-BC32)," ") -> 1858 | BF32: 20 | BG32: =IFERROR(+BJ32/(BF32*3.6)," ") -> 17.541667 | BH32: =IF(BI32>0,BI31," ") -> 1557267 | BI32: 1558530 | BJ32: =IFERROR((BI32-BH32)," ") -> 1263 | BK32: 70 | BL32: =IFERROR(+BO32/(BK32*3.6)," ") -> 14.261905 | BM32: =IF(BN32>0,BN31," ") -> 6209981 | BN32: 6213575 | BO32: =IFERROR((BN32-BM32)," ") -> 3594
